Workbook

Sheet Activity Data
A1: Activity Data | H1: Forest Loss Summary Statistics by Land Use 2010-2015
A2: Plot ID | B2: LU2010 | C2: LU2015 | D2: LU2020 | E2: Change in LU 2010-2015 | F2: Change in LU 2015-2020 | H2: LULC | I2: Sample Size (n) | J2: Proportion of forest loss, p | K2: Stratum area, ha | L2: Variance of stratum sample, var_stratum_sample | M2: Area of forest loss (AFL), ha | N2: Variance of forest loss, var_AFL | O2: Standard Deviation, s | P2: Standard Error, SE (ha) | Q2: Uncertainty (%)
A3: TE1 | B3: TE | C3: S | D3: S | E3: =IF(B3=C3,0,1) -> 1 | F3: =IF(C3=D3,0,1) -> 0 | H3: Tropical Evergreen Loss | I3: =COUNT(E3:E122) -> 120 | J3: =(COUNTIF(E3:E122, 1)/COUNT(E3:E122)) -> 0.083333333 | K3: 6000 | L3: =+J3*(1-J3) -> 0.076388889 | M3: =+J3*K3 -> 500 | N3: =L3*((K3)^2) -> 2750000 | O3: =+SQRT(N3) -> 1658.3124 | P3: =+O3/SQRT(I3-1) -> 152.01725 | Q3: =((1.96*P3)/M3)*100 -> 59.590761
A4: TE2 | B4: TE | C4: TE | D4: TE | E4: =IF(B4=C4,0,1) -> 0 | F4: =IF(C4=D4,0,1) -> 0 | H4: Tropical Deciduous Loss | I4: =COUNT(E123:E202) -> 80 | J4: =(COUNTIF(E123:E202, 1)/COUNT(E123:E202)) -> 0.1 | K4: 4000 | L4: =+J4*(1-J4) -> 0.09 | M4: =+K4*J4 -> 400 | N4: =L4*((K4)^2) -> 1440000 | O4: =+SQRT(N4) -> 1200 | P4: =+O4/SQRT(I4-1) -> 135.01055 | Q4: =((1.96*P4)/M4)*100 -> 66.155169
A5: TE3 | B5: TE | C5: TE | D5: TE | E5: =IF(B5=C5,0,1) -> 0 | F5: =IF(C5=D5,0,1) -> 0
A6: TE4 | B6: TE | C6: TE | D6: S | E6: =IF(B6=C6,0,1) -> 0 | F6: =IF(C6=D6,0,1) -> 1
A7: TE5 | B7: TE | C7: TE | D7: TE | E7: =IF(B7=C7,0,1) -> 0 | F7: =IF(C7=D7,0,1) -> 0
A8: TE6 | B8: TE | C8: TE | D8: TE | E8: =IF(B8=C8,0,1) -> 0 | F8: =IF(C8=D8,0,1) -> 0 | H8: Forest Loss Summary Statistics by Land Use 2015-2020
A9: TE7 | B9: TE | C9: S | D9: S | E9: =IF(B9=C9,0,1) -> 1 | F9: =IF(C9=D9,0,1) -> 0 | H9: LULC | I9: Sample Size (n) | J9: Proportion of forest loss, p | K9: Stratum area, ha | L9: Variance of stratum sample, var_stratum_sample | M9: Area of forest loss (AFL), ha | N9: Variance of forest loss, var_AFL | O9: Standard Deviation, s | P9: Standard Error, SE (ha) | Q9: Uncertainty (%)
A10: TE8 | B10: TE | C10: TE | D10: TE | E10: =IF(B10=C10,0,1) -> 0 | F10: =IF(C10=D10,0,1) -> 0 | H10: Tropical Evergreen Loss | I10: =COUNT(F3:F122) -> 120 | J10: =(COUNTIF(F3:F122, 1)/COUNT(F3:F122)) -> 0.058333333 | K10: 6000 | L10: =+J10*(1-J10) -> 0.054930556 | M10: =+J10*K10 -> 350 | N10: =L10*((K10)^2) -> 1977500 | O10: =+SQRT(N10) -> 1406.2361 | P10: =+O10/SQRT(I10-1) -> 128.90945 | Q10: =((1.96*P10)/M10)*100 -> 72.189294
A11: TE9 | B11: TE | C11: TE | D11: TE | E11: =IF(B11=C11,0,1) -> 0 | F11: =IF(C11=D11,0,1) -> 0 | H11: Tropical Deciduous Loss | I11: =COUNT(F123:F202) -> 80 | J11: =(COUNTIF(F123:F202, 1)/COUNT(F123:F202)) -> 0.05 | K11: 4000 | L11: =+J11*(1-J11) -> 0.0475 | M11: =+K11*J11 -> 200 | N11: =L11*((K11)^2) -> 760000 | O11: =+SQRT(N11) -> 871.77979 | P11: =+O11/SQRT(I11-1) -> 98.082889 | Q11: =((1.96*P11)/M11)*100 -> 96.121231
A12: TE10 | B12: TE | C12: TE | D12: TE | E12: =IF(B12=C12,0,1) -> 0 | F12: =IF(C12=D12,0,1) -> 0
A13: TE11 | B13: TE | C13: TE | D13: S | E13: =IF(B13=C13,0,1) -> 0 | F13: =IF(C13=D13,0,1) -> 1
A14: TE12 | B14: TE | C14: TE | D14: S | E14: =IF(B14=C14,0,1) -> 0 | F14: =IF(C14=D14,0,1) -> 1
A15: TE13 | B15: TE | C15: TE | D15: TE | E15: =IF(B15=C15,0,1) -> 0 | F15: =IF(C15=D15,0,1) -> 0 | H15: Legend for Strata | J15: Legend for Change in LU
A16: TE14 | B16: TE | C16: TE | D16: TE | E16: =IF(B16=C16,0,1) -> 0 | F16: =IF(C16=D16,0,1) -> 0 | H16: Tropical Evergreen Forest; TE | J16: No change | K16: 0
A17: TE15 | B17: TE | C17: TE | D17: TE | E17: =IF(B17=C17,0,1) -> 0 | F17: =IF(C17=D17,0,1) -> 0 | H17: Tropical Deciduous Forest; TD | J17: Forest loss | K17: 1
A18: TE16 | B18: TE | C18: S | D18: S | E18: =IF(B18=C18,0,1) -> 1 | F18: =IF(C18=D18,0,1) -> 0 | H18: Settlement; S
A19: TE17 | B19: TE | C19: TE | D19: TE | E19: =IF(B19=C19,0,1) -> 0 | F19: =IF(C19=D19,0,1) -> 0
A20: TE18 | B20: TE | C20: TE | D20: TE | E20: =IF(B20=C20,0,1) -> 0 | F20: =IF(C20=D20,0,1) -> 0
A21: TE19 | B21: TE | C21: TE | D21: TE | E21: =IF(B21=C21,0,1) -> 0 | F21: =IF(C21=D21,0,1) -> 0
A22: TE20 | B22: TE | C22: TE | D22: S | E22: =IF(B22=C22,0,1) -> 0 | F22: =IF(C22=D22,0,1) -> 1
A23: TE21 | B23: TE | C23: TE | D23: TE | E23: =IF(B23=C23,0,1) -> 0 | F23: =IF(C23=D23,0,1) -> 0
A24: TE22 | B24: TE | C24: TE | D24: TE | E24: =IF(B24=C24,0,1) -> 0 | F24: =IF(C24=D24,0,1) -> 0
A25: TE23 | B25: TE | C25: TE | D25: TE | E25: =IF(B25=C25,0,1) -> 0 | F25: =IF(C25=D25,0,1) -> 0
A26: TE24 | B26: TE | C26: TE | D26: TE | E26: =IF(B26=C26,0,1) -> 0 | F26: =IF(C26=D26,0,1) -> 0
A27: TE25 | B27: TE | C27: S | D27: S | E27: =IF(B27=C27,0,1) -> 1 | F27: =IF(C27=D27,0,1) -> 0
A28: TE26 | B28: TE | C28: TE | D28: TE | E28: =IF(B28=C28,0,1) -> 0 | F28: =IF(C28=D28,0,1) -> 0
A29: TE27 | B29: TE | C29: TE | D29: TE | E29: =IF(B29=C29,0,1) -> 0 | F29: =IF(C29=D29,0,1) -> 0
A30: TE28 | B30: TE | C30: TE | D30: TE | E30: =IF(B30=C30,0,1) -> 0 | F30: =IF(C30=D30,0,1) -> 0
... A222: C20 | B222: C | C222: C | D222: C | E222: =IF(B222=C222,0,1) -> 0 | F222: =IF(C222=D222,0,1) -> 0

Sheet Cstock EFs
A1: Allometric model parameters | F1: Other published values
A2: Model parameter values | F2: Ratios and Factors | G2: Value | H2: SE | I2: U%
A3: Alpha | B3: -1.667 | F3: R:S | G3: 0.321 | H3: 0.07 | I3: =ROUND(H3*$G$7/G3*100,3) -> 42.746
A4: Beta | B4: 2.51 | F4: CF | G4: 0.47 | H4: 0.013 | I4: =ROUND(H4*$G$7/G4*100,3) -> 5.422
F5: 1+R:S | G5: =(1+G3) -> 1.321 | I5: =ROUND(I3*G3/G5,3) -> 10.387
F6: Confidence level | G6: 0.95
F7: z | G7: =_xlfn.T.INV.2T(1-G6, 10000) -> 1.9602012
A8: Wood density Values | C8: Units | D8: Derived from:
A9: Tropical Evergreen and Settlements | B9: 0.46 | C9: g/cm3 | D9: Mahogany (Swietenia macrophylla)
A10: Tropical Deciduous | B10: 0.5 | C10: g/cm3 | D10: Teak (Tectona grandis)
A12: Sample data | F12: Carbon Stock Calculations per Plot | M12: Carbon Stock Summary Statistics by Land Use
A13: Plot ID | B13: Tree ID | C13: DBH (cm) | D13: AGB/tree (kg) | F13: Plot ID | G13: AGB (kg/plot) | H13: AGB (kg/ha) | I13: BGB (kg/ha) | J13: total biomass (kg/ha) | K13: Carbon stock (kgC/ha) | M13: Stratum | N13: Sample size, n | O13: Median carbon stock (tC/ha) | P13: Mean carbon stock (tC/ha) | Q13: Variance, var | R13: Standard deviation, s (kgC/ha) | S13: Standard Error, SE | T13: Uncertainty, %
A14: TE1 | B14: 1 | C14: 70 | D14: =EXP($B$3+$B$4*LN(C14)+LN($B$10)) -> 4038.287 | F14: TE1 | G14: =SUMIF($A$14:$A$150, F14, $D$14:$D$150) -> 14172.009 | H14: =G14/0.04/1000 -> 354.30023 | I14: =H14*$G$3 -> 113.73037 | J14: =H14+I14 -> 468.03061 | K14: =J14*$G$4 -> 219.97439 | M14: Tropical Evergreen | N14: 8 | O14: =MEDIAN(K14:K21) -> 140.07485 | P14: =AVERAGE(K14:K21) -> 167.01988 | Q14: =_xlfn.VAR.S(K14:K21) -> 10576.656 | R14: =SQRT(Q14) -> 102.84287 | S14: =R14/SQRT((N14-1)) -> 38.870951 | T14: =(1.96*S14/P14)*100 -> 45.615566
A15: TE1 | B15: 2 | C15: 65 | D15: =EXP($B$3+$B$4*LN(C15)+LN($B$10)) -> 3352.8462 | F15: TE2 | G15: =SUMIF($A$14:$A$150, F15, $D$14:$D$150) -> 2204.5069 | H15: =G15/0.04/1000 -> 55.112671 | I15: =H15*$G$3 -> 17.691168 | J15: =H15+I15 -> 72.803839 | K15: =J15*$G$4 -> 34.217804 | M15: Tropical Deciduous | N15: 8 | O15: =MEDIAN(K22:K29) -> 600.40678 | P15: =AVERAGE(K22:K29) -> 599.32837 | Q15: =_xlfn.VAR.S(K22:K29) -> 7089.1585 | R15: =SQRT(Q15) -> 84.197141 | S15: =R15/SQRT((N15-1)) -> 31.823528 | T15: =(1.96*S15/P15)*100 -> 10.407336
A16: TE1 | B16: 3 | C16: 60 | D16: =EXP($B$3+$B$4*LN(C16)+LN($B$10)) -> 2742.5891 | F16: TE3 | G16: =SUMIF($A$14:$A$150, F16, $D$14:$D$150) -> 7391.1332 | H16: =G16/0.04/1000 -> 184.77833 | I16: =H16*$G$3 -> 59.313844 | J16: =H16+I16 -> 244.09217 | K16: =J16*$G$4 -> 114.72332 | M16: Settlement | P16: 5 | T16: 75
A17: TE1 | B17: 4 | C17: 70 | D17: =EXP($B$3+$B$4*LN(C17)+LN($B$10)) -> 4038.287 | F17: TE4 | G17: =SUMIF($A$14:$A$150, F17, $D$14:$D$150) -> 7427.6202 | H17: =G17/0.04/1000 -> 185.6905 | I17: =H17*$G$3 -> 59.606652 | J17: =H17+I17 -> 245.29716 | K17: =J17*$G$4 -> 115.28966
A18: TE2 | B18: 5 | C18: 55 | D18: =EXP($B$3+$B$4*LN(C18)+LN($B$10)) -> 2204.5069 | F18: TE5 | G18: =SUMIF($A$14:$A$150, F18, $D$14:$D$150) -> 9748.9048 | H18: =G18/0.04/1000 -> 243.72262 | I18: =H18*$G$3 -> 78.234961 | J18: =H18+I18 -> 321.95758 | K18: =J18*$G$4 -> 151.32006
A19: TE3 | B19: 6 | C19: 65 | D19: =EXP($B$3+$B$4*LN(C19)+LN($B$10)) -> 3352.8462 | F19: TE6 | G19: =SUMIF($A$14:$A$150, F19, $D$14:$D$150) -> 8299.9421 | H19: =G19/0.04/1000 -> 207.49855 | I19: =H19*$G$3 -> 66.607035 | J19: =H19+I19 -> 274.10559 | K19: =J19*$G$4 -> 128.82963 | M19: Carbon Stock Change Factors (CSCF)
A20: TE4 | B20: 7 | C20: 60 | D20: =EXP($B$3+$B$4*LN(C20)+LN($B$10)) -> 2742.5891 | F20: TE7 | G20: =SUMIF($A$14:$A$150, F20, $D$14:$D$150) -> 12271.242 | H20: =G20/0.04/1000 -> 306.78104 | I20: =H20*$G$3 -> 98.476715 | J20: =H20+I20 -> 405.25776 | K20: =J20*$G$4 -> 190.47115 | M20: Conversion type | N20: Mean carbon stock of prior land use (t/ha) | O20: Mean carbon stock of post land use (t/ha) | P20: EF (tC/ha) | Q20: Uncertainty, %
A21: TE3 | B21: 8 | C21: 70 | D21: =EXP($B$3+$B$4*LN(C21)+LN($B$10)) -> 4038.287 | F21: TE8 | G21: =SUMIF($A$14:$A$150, F21, $D$14:$D$150) -> 24567.658 | H21: =G21/0.04/1000 -> 614.19146 | I21: =H21*$G$3 -> 197.15546 | J21: =H21+I21 -> 811.34691 | K21: =J21*$G$4 -> 381.33305 | M21: Tropical Evergreen to Settlement | N21: =P14 -> 167.01988 | O21: =$P$16 -> 5 | P21: =(N21-O21) -> 162.01988 | Q21: =SQRT((T14*P14)^2+(T$16*P$16)^2)/(P14-P$16) -> 47.080208
A22: TE4 | B22: 9 | C22: 65 | D22: =EXP($B$3+$B$4*LN(C22)+LN($B$10)) -> 3352.8462 | F22: TD1 | G22: =SUMIF($A$14:$A$150, F22, $D$14:$D$150) -> 42975.545 | H22: =G22/0.04/1000 -> 1074.3886 | I22: =H22*$G$3 -> 344.87875 | J22: =H22+I22 -> 1419.2674 | K22: =J22*$G$4 -> 667.05566 | M22: Tropical Deciduous to Settlement | N22: =P15 -> 599.32837 | O22: =$P$16 -> 5 | P22: =(N22-O22) -> 594.32837 | Q22: =SQRT((T15*P15)^2+(T$16*P$16)^2)/(P15-P$16) -> 10.513841
A23: TE5 | B23: 10 | C23: 60 | D23: =EXP($B$3+$B$4*LN(C23)+LN($B$10)) -> 2742.5891 | F23: TD2 | G23: =SUMIF($A$14:$A$150, F23, $D$14:$D$150) -> 45103.66 | H23: =G23/0.04/1000 -> 1127.5915 | I23: =H23*$G$3 -> 361.95687 | J23: =H23+I23 -> 1489.5484 | K23: =J23*$G$4 -> 700.08773
A24: TE4 | B24: 11 | C24: 45 | D24: =EXP($B$3+$B$4*LN(C24)+LN($B$10)) -> 1332.1849 | F24: TD3 | G24: =SUMIF($A$14:$A$150, F24, $D$14:$D$150) -> 42219.288 | H24: =G24/0.04/1000 -> 1055.4822 | I24: =H24*$G$3 -> 338.80979 | J24: =H24+I24 -> 1394.292 | K24: =J24*$G$4 -> 655.31723
A25: TE5 | B25: 12 | C25: 55 | D25: =EXP($B$3+$B$4*LN(C25)+LN($B$10)) -> 2204.5069 | F25: TD4 | G25: =SUMIF($A$14:$A$150, F25, $D$14:$D$150) -> 39995.54 | H25: =G25/0.04/1000 -> 999.88851 | I25: =H25*$G$3 -> 320.96421 | J25: =H25+I25 -> 1320.8527 | K25: =J25*$G$4 -> 620.80078
A26: TE6 | B26: 13 | C26: 60 | D26: =EXP($B$3+$B$4*LN(C26)+LN($B$10)) -> 2742.5891 | F26: TD5 | G26: =SUMIF($A$14:$A$150, F26, $D$14:$D$150) -> 36737.139 | H26: =G26/0.04/1000 -> 918.42847 | I26: =H26*$G$3 -> 294.81554 | J26: =H26+I26 -> 1213.244 | K26: =J26*$G$4 -> 570.22468
A27: TE7 | B27: 14 | C27: 50 | D27: =EXP($B$3+$B$4*LN(C27)+LN($B$10)) -> 1735.4648 | F27: TD6 | G27: =SUMIF($A$14:$A$150, F27, $D$14:$D$150) -> 27567.805 | H27: =G27/0.04/1000 -> 689.19513 | I27: =H27*$G$3 -> 221.23164 | J27: =H27+I27 -> 910.42677 | K27: =J27*$G$4 -> 427.90058
A28: TE8 | B28: 15 | C28: 65 | D28: =EXP($B$3+$B$4*LN(C28)+LN($B$10)) -> 3352.8462 | F28: TD7 | G28: =SUMIF($A$14:$A$150, F28, $D$14:$D$150) -> 37367.744 | H28: =G28/0.04/1000 -> 934.19361 | I28: =H28*$G$3 -> 299.87615 | J28: =H28+I28 -> 1234.0698 | K28: =J28*$G$4 -> 580.01279
A29: TE5 | B29: 16 | C29: 75 | D29: =EXP($B$3+$B$4*LN(C29)+LN($B$10)) -> 4801.8089 | F29: TD8 | G29: =SUMIF($A$14:$A$150, F29, $D$14:$D$150) -> 36930.599 | H29: =G29/0.04/1000 -> 923.26498 | I29: =H29*$G$3 -> 296.36806 | J29: =H29+I29 -> 1219.633 | K29: =J29*$G$4 -> 573.22753
A30: TE6 | B30: 17 | C30: 65 | D30: =EXP($B$3+$B$4*LN(C30)+LN($B$10)) -> 3352.8462
A31: TE7 | B31: 18 | C31: 68 | D31: =EXP($B$3+$B$4*LN(C31)+LN($B$10)) -> 3754.9009
A32: TE6 | B32: 19 | C32: 55 | D32: =EXP($B$3+$B$4*LN(C32)+LN($B$10)) -> 2204.5069 | M32: AGB Summary Statistics by Land Use
A33: TE7 | B33: 20 | C33: 60 | D33: =EXP($B$3+$B$4*LN(C33)+LN($B$10)) -> 2742.5891 | M33: Stratum | N33: Sample size, n | O33: Median AGB (tdm/ha) | P33: Mean AGB (tdm/ha) | Q33: Variance, var | R33: Standard deviation, s (kg dm/ha) | S33: Standard Error, SE | T33: Uncertainty, %
A34: TE8 | B34: 21 | C34: 60 | D34: =EXP($B$3+$B$4*LN(C34)+LN($B$10)) -> 2742.5891 | M34: Tropical Evergreen | N34: 8 | O34: =MEDIAN(H14:H21) -> 225.61059 | P34: =AVERAGE(H14:H21) -> 269.00943 | Q34: =_xlfn.VAR.S(H14:H21) -> 27437.657 | R34: =SQRT(Q34) -> 165.64316 | S34: =R34/SQRT((N34-1)) -> 62.607231 | T34: =($G$7*S34/P34)*100 -> 45.620249
A35: TE9 | B35: 22 | C35: 45 | D35: =EXP($B$3+$B$4*LN(C35)+LN($B$10)) -> 1332.1849 | M35: Tropical Deciduous | N35: 8 | O35: =MEDIAN(H22:H29) -> 967.04106 | P35: =AVERAGE(H22:H29) -> 965.30413 | Q35: =_xlfn.VAR.S(H22:H29) -> 18390.491 | R35: =SQRT(Q35) -> 135.61155 | S35: =R35/SQRT((N35-1)) -> 51.256347 | T35: =($G$7*S35/P35)*100 -> 10.408404
A36: TE7 | B36: 23 | C36: 70 | D36: =EXP($B$3+$B$4*LN(C36)+LN($B$10)) -> 4038.287 | M36: Settlement
A37: TE8 | B37: 24 | C37: 75 | D37: =EXP($B$3+$B$4*LN(C37)+LN($B$10)) -> 4801.8089
A38: TE9 | B38: 25 | C38: 65 | D38: =EXP($B$3+$B$4*LN(C38)+LN($B$10)) -> 3352.8462
A39: TE8 | B39: 26 | C39: 55 | D39: =EXP($B$3+$B$4*LN(C39)+LN($B$10)) -> 2204.5069 | M39: Carbon Stock Summary Statistics by Land Use (error propagation - IPCC approach1) - Incorrect as AGB and BGB fully correlated
A40: TE8 | B40: 27 | C40: 45 | D40: =EXP($B$3+$B$4*LN(C40)+LN($B$10)) -> 1332.1849 | M40: Stratum | N40: BGB (tdm/ha) | O40: U% BGB | P40: Total Biomass (tdm/ha) | Q40: U% tot Biomass | R40: Carbon Stock | S40: U% carbon stock | T40: SE Carbon stock
A41: TE8 | B41: 28 | C41: 65 | D41: =EXP($B$3+$B$4*LN(C41)+LN($B$10)) -> 3352.8462 | M41: Tropical Evergreen | N41: =P34*$G$3 -> 86.352026 | O41: =SQRT(T34^2+$I$3^2) -> 62.517419 | P41: =N41+P34 -> 355.36145 | Q41: =SQRT((N41*O41)^2+(P34*T34)^2)/P41 -> 37.728309 | R41: =P41*$G$4 -> 167.01988 | S41: =SQRT(Q41^2+$I$4^2) -> 38.11592 | T41: =S41*R41/$G$7/100 -> 32.476852
...

Sheet BaseLine & ER
A3: Carbon Stock Change
A4: Conversion type | B4: Emissions factors | D4: 2010-2015 | H4: 2015-2020 | L4: ER (2010-2015) vs (2015-2020)
B5: CSCF (tC/ha) | C5: Uncertainty CSCF (%) | D5: AD (ha/year) | E5: Uncertainty AD (%) | F5: Emissions (tCO2/year) | G5: Uncertainty Emissions (%) | H5: AD (ha/year) | I5: Uncertainty AD (%) | J5: Emissions (tCO2/year) | K5: Uncertainty Emissions (%) | L5: Emission Reductions (tCO2/year) | M5: Uncertainty ER (%)
A6: Tropical Evergreen to Settlement | B6: ='Cstock EFs'!P21 -> 162.01988 | C6: ='Cstock EFs'!Q21 -> 47.080208 | D6: ='Activity Data'!M3/5 -> 100 | E6: ='Activity Data'!Q3 -> 59.590761 | F6: =+D6*B6*44/12 -> 59407.29 | G6: =SQRT(E6^2+C6^2) -> 75.944749 | H6: ='Activity Data'!M10/5 -> 70 | I6: ='Activity Data'!Q10 -> 72.189294 | J6: =+H6*B6*44/12 -> 41585.103 | K6: =SQRT(I6^2+C6^2) -> 86.184918 | L6: =F6-J6 -> 17822.187 | M6: =SQRT((F6*G6)^2+(J6*K6)^2)/ABS(L6) -> 323.3032
A7: Tropical Deciduous to Settlement | B7: ='Cstock EFs'!P22 -> 594.32837 | C7: ='Cstock EFs'!Q22 -> 10.513841 | D7: ='Activity Data'!M4/5 -> 80 | E7: ='Activity Data'!Q4 -> 66.155169 | F7: =+D7*B7*44/12 -> 174336.32 | G7: =SQRT(E7^2+C7^2) -> 66.985425 | H7: ='Activity Data'!M11/5 -> 40 | I7: ='Activity Data'!Q11 -> 96.121231 | J7: =+H7*B7*44/12 -> 87168.161 | K7: =SQRT(I7^2+C7^2) -> 96.694529 | L7: =F7-J7 -> 87168.161 | M7: =SQRT((F7*G7)^2+(J7*K7)^2)/ABS(L7) -> 165.22113
A8: Total Emissions / ERs per year | F8: =+F6+F7 -> 233743.61 | G8: =+SQRT((F6*G6)^2+(F7*G7)^2)/ABS(F8) -> 53.559594 | J8: =+J6+J7 -> 128753.26 | K8: =+SQRT((J6*K6)^2+(J7*K7)^2)/ABS(J8) -> 71.136297 | L8: =+SUM(L6:L7) -> 104990.35 | M8: =SQRT((L6*M6)^2+(L7*M7)^2)/ABS(L8) -> 147.74581
A9: Total Emissions / ERs tCO2 | F9: =5*F8 -> 1168718.1 | G9: =G8 -> 53.559594 | J9: =5*J8 -> 643766.32 | K9: =K8 -> 71.136297 | L9: =5*L8 -> 524951.74 | M9: =M8 -> 147.74581
A15: Emissions and emission reductions (tCO2) (U propagation approach 1)
A16: Conversion type | B16: EF | C16: EF U% | D16: AD10-15 | E16: AD 10-15 U% | F16: AD15-20 | G16: AD 15-20 U% | H16: E 10-15 | I16: E 10-15 U% | J16: E 10-15 | K16: E 10-15 U%
A17: Tropical Evergreen to Settlement | B17: ='Cstock EFs'!P54 -> 162.01988 | C17: ='Cstock EFs'!Q54 -> 48.60959 | D17: ='Activity Data'!M3/5 -> 100 | E17: ='Activity Data'!Q3 -> 59.590761 | F17: ='Activity Data'!M10/5 -> 70 | G17: ='Activity Data'!Q10 -> 72.189294 | H17: =$B17*D17*44/12 -> 59407.29 | I17: =SQRT($C17^2+E17^2) -> 76.902217 | J17: =$B17*F17*44/12 -> 41585.103 | K17: =SQRT($C17^2+G17^2) -> 87.029801
A18: Tropical Deciduous to Settlement | B18: ='Cstock EFs'!P55 -> 594.32837 | C18: ='Cstock EFs'!Q55 -> 14.841705 | D18: ='Activity Data'!M4/5 -> 80 | E18: ='Activity Data'!Q4 -> 66.155169 | F18: ='Activity Data'!M11/5 -> 40 | G18: ='Activity Data'!Q11 -> 96.121231 | H18: =$B18*D18*44/12 -> 174336.32 | I18: =SQRT($C18^2+E18^2) -> 67.799576 | J18: =$B18*F18*44/12 -> 87168.161 | K18: =SQRT($C18^2+G18^2) -> 97.260307
B21: Value (tCO2/year) | C21: U%
A22: FRL | B22: =SUM(H17:H18) -> 233743.61 | C22: =SQRT((H17*I17)^2+(H18*I18)^2)/SUM(H17:H18) -> 54.213719
A23: Monitoring | B23: =SUM(J17:J18) -> 128753.26 | C23: =SQRT((J17*K17)^2+(J18*K18)^2)/SUM(J17:J18) -> 71.595647
A24: Emission Reductions | B24: =B22-B23 -> 104990.35 | C24: =SQRT((B22*C22)^2+(B23*C23)^2)/ABS(B22-B23) -> 149.25431
A26: time period monitoring (years) | B26: 5
A27: Total emission reductions (tCO2) | B27: =B24*B26 -> 524951.74 | C27: =C24 -> 149.25431

Sheet setup
A1: n_iter | B1: tree_carbon_unit | C1: dg_ext | D1: dg_pool | E1: ad_annual | F1: conf_level | G1: digits | H1: ran_seed | I1: trunc_pdf
A2: 10000 | B2: DM | C2: Degraded | D2: ALL | E2: FALSE | F2: 0.9 | G2: 3 | H2: 444 | I2: FALSE

Sheet time
A1: period_no | B1: year_start | C1: year_end | D1: period_type
A2: T1 | B2: 2010 | C2: 2015 | D2: REF
A3: T2 | B3: 2015 | C3: 2020 | D3: MON1

Sheet area
A1: trans_no | B1: trans_period | C1: lu_initial | D1: lu_final | E1: trans_area | F1: trans_se | G1: trans_pdf | H1: trans_pdf_a | I1: trans_pdf_b | J1: trans_pdf_c | K1: redd_activity
A2: 1 | B2: T1 | C2: Tropical Evergreen Forest | D2: Settlements | E2: 500 | F2: 152.017 | G2: normal | K2: DF
A3: 2 | B3: T1 | C3: Tropical Deciduous Forest | D3: Settlements | E3: 400 | F3: 135.011 | G3: normal | K3: DF
A4: 3 | B4: T2 | C4: Tropical Evergreen Forest | D4: Settlements | E4: 350 | F4: 128.909 | G4: normal | K4: DF
A5: 4 | B5: T2 | C5: Tropical Deciduous Forest | D5: Settlements | E5: 200 | F5: 98.083 | G5: normal | K5: DF

Sheet carbon
A1: c_no | B1: c_period | C1: c_lu | D1: c_element | E1: c_unit | F1: c_value | G1: c_se | H1: c_pdf | I1: c_pdf_a | J1: c_pdf_b | K1: c_pdf_c
A2: 1 | B2: ALL | C2: Tropical Evergreen Forest | D2: AGB | E2: DM | F2: 599.328 | G2: 31.824 | H2: normal
A3: 2 | B3: ALL | C3: Tropical Deciduous Forest | D3: AGB | E3: DM | F3: 167.02 | G3: 38.871 | H3: normal
A4: 4 | B4: ALL | C4: Tropical Evergreen Forest | D4: RS | E4: DM | F4: 0.321 | G4: 0.07 | H4: normal
A5: 5 | B5: ALL | C5: Tropical Deciduous Forest | D5: RS | E5: DM | F5: 0.321 | G5: 0.07 | H5: normal
A6: 6 | B6: ALL | C6: Settlements | D6: ALL | E6: C | F6: 5 | G6: =75/100*F6/1.645 -> 2.2796353 | H6: normal
A7: 7 | B7: ALL | C7: ALL | D7: CF | E7: ratio | F7: 0.47 | G7: 0.013 | H7: normal
